  0%|                                                   | 0/100 [00:00<?, ?it/s]/home/indika/anaconda3/lib/python3.7/site-packages/torch/nn/modules/loss.py:446: UserWarning: Using a target size (torch.Size([32])) that is different to the input size (torch.Size([32, 1])). This will likely lead to incorrect results due to broadcasting. Please ensure they have the same size.
  return F.mse_loss(input, target, reduction=self.reduction)
/home/indika/anaconda3/lib/python3.7/site-packages/torch/nn/modules/loss.py:446: UserWarning: Using a target size (torch.Size([12])) that is different to the input size (torch.Size([12, 1])). This will likely lead to incorrect results due to broadcasting. Please ensure they have the same size.
  return F.mse_loss(input, target, reduction=self.reduction)
/home/indika/anaconda3/lib/python3.7/site-packages/torch/nn/modules/loss.py:446: UserWarning: Using a target size (torch.Size([5964])) that is different to the input size (torch.Size([5964, 1])). This will likely lead to incorrect results due to broadcasting. Please ensure they have the same size.
  return F.mse_loss(input, target, reduction=self.reduction)
/home/indika/anaconda3/lib/python3.7/site-packages/torch/nn/modules/loss.py:446: UserWarning: Using a target size (torch.Size([1988])) that is different to the input size (torch.Size([1988, 1])). This will likely lead to incorrect results due to broadcasting. Please ensure they have the same size.
  return F.mse_loss(input, target, reduction=self.reduction)

















 25%|██████████▌                               | 25/100 [00:36<01:47,  1.43s/it]

 26%|██████████▉                               | 26/100 [00:39<01:51,  1.50s/it]
Exception in thread Thread-11:
Traceback (most recent call last):
  File "/home/indika/anaconda3/lib/python3.7/threading.py", line 926, in _bootstrap_inner
    self.run()
  File "/home/indika/anaconda3/lib/python3.7/threading.py", line 870, in run
    self._target(*self._args, **self._kwargs)
  File "/home/indika/anaconda3/lib/python3.7/site-packages/wandb/sdk/wandb_run.py", line 185, in check_network_status
    status_response = self._interface.communicate_network_status()
  File "/home/indika/anaconda3/lib/python3.7/site-packages/wandb/sdk/interface/interface.py", line 749, in communicate_network_status
    resp = self._communicate(req, timeout=timeout, local=True)
  File "/home/indika/anaconda3/lib/python3.7/site-packages/wandb/sdk/interface/interface.py", line 539, in _communicate
    return self._communicate_async(rec, local=local).get(timeout=timeout)
  File "/home/indika/anaconda3/lib/python3.7/site-packages/wandb/sdk/interface/interface.py", line 544, in _communicate_async
    raise Exception("The wandb backend process has shutdown")
Exception: The wandb backend process has shutdown
Exception in thread Thread-10:
Traceback (most recent call last):
  File "/home/indika/anaconda3/lib/python3.7/threading.py", line 926, in _bootstrap_inner
    self.run()
  File "/home/indika/anaconda3/lib/python3.7/threading.py", line 870, in run
    self._target(*self._args, **self._kwargs)
  File "/home/indika/anaconda3/lib/python3.7/site-packages/wandb/sdk/wandb_run.py", line 203, in check_status
    status_response = self._interface.communicate_stop_status()
  File "/home/indika/anaconda3/lib/python3.7/site-packages/wandb/sdk/interface/interface.py", line 737, in communicate_stop_status
    resp = self._communicate(req, timeout=timeout, local=True)
  File "/home/indika/anaconda3/lib/python3.7/site-packages/wandb/sdk/interface/interface.py", line 539, in _communicate
    return self._communicate_async(rec, local=local).get(timeout=timeout)
  File "/home/indika/anaconda3/lib/python3.7/site-packages/wandb/sdk/interface/interface.py", line 544, in _communicate_async
    raise Exception("The wandb backend process has shutdown")
Exception: The wandb backend process has shutdown